Workbook

Sheet Device list
B1: 1 | C1: 2 | D1: 3 | E1: 4 | F1: 5 | H1: 6 | I1: 7 | J1: 8 | K1: 9 | L1: 10 | M1: 11
F2: ABB | G2: SMA | H2: Huawei | J2: Solar Edge
C3: Edge Computing | D3: UPS Battery | E3: Total | F3: Inverter | G3: Inverter | H3: Smart Logger | I3: Inverter | J3: Inverter | K3: Revenue Meter | L3: Pyranometer | M3: Grid Meter | N3: PIC Middleware | O3: Target Date install | P3: Yoko Remark | Q3: Remark | R3: mc id | S3: API Key | T3: Key ref
A4: 1 | B4: Solar1 | E4: =SUM(F4,I4,G4,J4) -> 5 | G4: 5 | L4: 2 | M4: 1 | O4: Done | P4: Solar1 ไม่มี internet | S4: ygm_FUHz9QdfDPQpc1IaSsdn0OIERUmQ1kA2zM7k85yTeyM | T4: O8sJQiAWhQTGDygbIDIea2u+QvxuaFJ+vHmdaAE+R2HcHnrfuD3bc82QeH/YFyaW32pTODZy/hLEWAKSwTijEg==
A5: 2 | B5: VISTEC1 | C5: 1 | E5: =SUM(F5,I5,J5) -> 6 | F5: 6 | H5: - | I5: - | K5: 6 | M5: 1 | N5: ABB : SAX | O5: 04/08/2026 13:30-15:30 | P5: อยู่ Zone เดียวกัน | Q5: ใช้ Pyranometer Vistec2 | R5: 0A775DA8A4CDE838 | S5: ygm_Y9VkJob0alwMR5M52lszfyPE4iodYXAdy-JBYzwTGo0
A6: 3 | B6: VISTEC2 | E6: =SUM(F6,I6,J6) -> 11 | F6: 10 | H6: 1 | I6: 1 | K6: 3 | L6: 1 | N6: Huawei : NA
A7: 4 | B7: KVIS | C7: 1 | E7: =SUM(F7,I7,J7) -> 1 | F7: 1 | K7: 1 | M7: 1 | N7: SMA : Nuttsu | Q7: ใช้ Pyranometer Vistec2
A8: 5 | B8: Thaioil1 | C8: 1 | E8: =SUM(F8,I8,J8) -> 7 | H8: 1 | I8: 7 | K8: 1 | L8: 1 | M8: 1 | N8: SolarEdge : | O8: 11/08/2026 13:30-16:30
A9: 6 | B9: Thaioil2 | C9: 1 | E9: =SUM(F9,I9,J9) -> 5 | H9: 1 | I9: 5 | K9: 4 | L9: 1 | M9: 2
A10: 7 | B10: PTTOR MINBURI | C10: 1 | E10: =SUM(F10,I10,J10) -> 2 | H10: 1 | I10: 2 | K10: 2 | M10: 1
A11: 8 | B11: PTTOR TALINCHAN | C11: 1 | E11: =SUM(F11,I11,J11) -> 1 | H11: 1 | I11: 1 | K11: 1 | M11: 1 | O11: 04/08/2026 15:30-16:30 | R11: 4A6E34BF9B08BB06 | S11: ygm_2SahybmGZfoApzOLk65zwIxvyodAXD2f0yhIamiDTvU
A12: 9 | B12: AICA | C12: 1 | D12: 1 | E12: =SUM(F12,I12,J12) -> 30 | H12: 2 | I12: 30 | K12: 2 | L12: 1 | M12: 1 | R12: 30AD4DF0D366091B | S12: ygm_00M8LbgAd96VvD56Nma1uccjIuvVkVbiqts87UbmWxI
A13: 10 | B13: SURETEX | C13: 1 | D13: 1 | E13: =SUM(F13,I13,J13) -> 17 | H13: 1 | I13: 17 | K13: 2 | L13: 1 | M13: 1 | O13: 05/08/2026 13:30-16:30 | R13: 0A8E57B5C2B538A2 | S13: ygm_RYsAtCAGydKABEGahLab43lBB9EHHeyyOouOL347RY4
A14: 11 | B14: SUT | C14: 1 | D14: 1 | E14: =SUM(F14,I14,J14) -> 31 | H14: 3 | I14: 31 | K14: 6 | L14: 2 | M14: 1 | R14: 4134D5B9244E5450 | S14: ygm_MoAMjwOy_Xh1tuEbsZM4_82BG6LloSLMfaAvhFTNzrs
A15: 12 | B15: PTIC | C15: 1 | D15: 1 | E15: =SUM(F15,I15,J15) -> 2 | H15: 1 | I15: 2 | K15: 1 | L15: 1 | M15: 1 | Q15: Add Smart Logger แยกของเราออกมา | R15: FDA2301E661BB7CD | S15: ygm_gY1iebmiCIELtHX1KsX4pS2LlsYDuBYy36VmiZ-BU10
A16: 13 | B16: RASC | C16: 1 | D16: 1 | E16: =SUM(F16,I16,J16) -> 3 | H16: 1 | I16: 3 | K16: 1 | L16: 1 | M16: 1 | P16: ตรวจสอบแล้วมี Internet | R16: 9ED732AAAB654915 | S16: ygm_09DCXdskJBE8_D8s0AhI7j7YdXiqG9Pzq23Pl7OpJeQ
A17: 14 | B17: INI | C17: 1 | D17: 1 | E17: =SUM(F17,I17,J17) -> 14 | H17: 2 | I17: 10 | J17: 4 | K17: 2 | L17: 5 | M17: 1 | O17: 07/08/2026 13:30-16:30
A18: 15 | B18: ENTER | C18: 1 | D18: 1 | E18: =SUM(F18,I18,J18) -> 9 | H18: 1 | I18: 9 | K18: 2 | L18: 1 | M18: 1
A19: 16 | B19: FUTUREFLEX | C19: 1 | D19: 1 | E19: =SUM(F19,I19,J19) -> 7 | H19: 2 | I19: 7 | K19: 2 | L19: 2 | M19: 2
C20: =SUM(C5:C19) -> 14 | D20: =SUM(D5:D19) -> 8
Q26: s

Sheet IP List
C1: Building | D1: No. | E1: Equipment | F1: Tag | G1: Description | H1: Capacity | I1: Unit | J1: Brand | K1: Model | L1: Serial | M1: IP | N1: Modbus Slave ID | O1: Port
A3: Vistec1 | B3: VT1 | C3: M1 | D3: 1 | E3: Inverter | F3: =B3&"-"&IF(C3="","",C3&"-")&IF(E3="Inverter","INV",IF(E3="Pyranometer","PRY",IF(E3="Revenue Meter","REV",IF(E3="Grid Meter","GMT","recheck"))))&"-"&TEXT(D3,"00") -> VT1-M1-INV-01 | G3: Buiding M1 Inverter | H3: 127.05 | I3: kWp | J3: ABB | K3: PVS-100-TL-POWER | M3: 10.204.30.64 | N3: 1 | O3: 502
A4: Vistec1 | B4: VT1 | C4: M2 | D4: 1 | E4: Inverter | F4: =B4&"-"&IF(C4="","",C4&"-")&IF(E4="Inverter","INV",IF(E4="Pyranometer","PRY",IF(E4="Revenue Meter","REV",IF(E4="Grid Meter","GMT","recheck"))))&"-"&TEXT(D4,"00") -> VT1-M2-INV-01 | G4: Buiding M2 Inverter | H4: 127.05 | I4: kWp | J4: ABB | K4: PVS-100-TL-POWER | M4: 10.204.30.65 | N4: 1 | O4: 502
A5: Vistec1 | B5: VT1 | C5: N | D5: 1 | E5: Inverter | F5: =B5&"-"&IF(C5="","",C5&"-")&IF(E5="Inverter","INV",IF(E5="Pyranometer","PRY",IF(E5="Revenue Meter","REV",IF(E5="Grid Meter","GMT","recheck"))))&"-"&TEXT(D5,"00") -> VT1-N-INV-01 | G5: Buiding N(Phase1) Inverter | H5: 57.75 | I5: kWp | J5: ABB | K5: PVS-50-TL-SX2 | M5: 10.204.30.66 | N5: 1 | O5: 502
A6: Vistec1 | B6: VT1 | C6: U | D6: 1 | E6: Inverter | F6: =B6&"-"&IF(C6="","",C6&"-")&IF(E6="Inverter","INV",IF(E6="Pyranometer","PRY",IF(E6="Revenue Meter","REV",IF(E6="Grid Meter","GMT","recheck"))))&"-"&TEXT(D6,"00") -> VT1-U-INV-01 | G6: Buiding U(Phase1) Inverter | H6: 41.58 | I6: kWp | J6: ABB | K6: PVS-50-TL-SX2 | M6: 10.204.30.62 | N6: 1 | O6: 502
A7: Vistec1 | B7: VT1 | C7: CP1 | D7: 1 | E7: Inverter | F7: =B7&"-"&IF(C7="","",C7&"-")&IF(E7="Inverter","INV",IF(E7="Pyranometer","PRY",IF(E7="Revenue Meter","REV",IF(E7="Grid Meter","GMT","recheck"))))&"-"&TEXT(D7,"00") -> VT1-CP1-INV-01 | G7: CP1 Buiding V Inverter | H7: 103.95 | I7: kWp | J7: ABB | K7: PVS-100-TL-POWER | M7: 10.204.30.63 | N7: 1 | O7: 502
A8: Vistec1 | B8: VT1 | C8: CP2 | D8: 1 | E8: Inverter | F8: =B8&"-"&IF(C8="","",C8&"-")&IF(E8="Inverter","INV",IF(E8="Pyranometer","PRY",IF(E8="Revenue Meter","REV",IF(E8="Grid Meter","GMT","recheck"))))&"-"&TEXT(D8,"00") -> VT1-CP2-INV-01 | G8: CP2 Buiding X Inverter | H8: 48.51 | I8: kWp | J8: ABB | K8: PVS-50-TL-SX2 | M8: 10.204.30.61 | N8: 1 | O8: 502
A9: Vistec1 | B9: VT1 | C9: M1 | D9: 1 | E9: Revenue Meter | F9: =B9&"-"&IF(C9="","",C9&"-")&IF(E9="Inverter","INV",IF(E9="Pyranometer","PRY",IF(E9="Revenue Meter","REV",IF(E9="Grid Meter","GMT","recheck"))))&"-"&TEXT(D9,"00") -> VT1-M1-REV-01 | G9: Building M1 Revenue Meter | J9: EDMI | K9: MK6E | L9: 219150730 | M9: 10.204.30.53 | N9: 5 | O9: 502
A10: Vistec1 | B10: VT1 | C10: M2 | D10: 1 | E10: Revenue Meter | F10: =B10&"-"&IF(C10="","",C10&"-")&IF(E10="Inverter","INV",IF(E10="Pyranometer","PRY",IF(E10="Revenue Meter","REV",IF(E10="Grid Meter","GMT","recheck"))))&"-"&TEXT(D10,"00") -> VT1-M2-REV-01 | G10: Building M2 Revenue Meter | J10: EDMI | K10: MK6E | L10: 219150723 | M10: 10.204.30.54 | N10: 3 | O10: 502
A11: Vistec1 | B11: VT1 | C11: V | D11: 1 | E11: Revenue Meter | F11: =B11&"-"&IF(C11="","",C11&"-")&IF(E11="Inverter","INV",IF(E11="Pyranometer","PRY",IF(E11="Revenue Meter","REV",IF(E11="Grid Meter","GMT","recheck"))))&"-"&TEXT(D11,"00") -> VT1-V-REV-01 | G11: Carpark Buiding V Revenue Meter | J11: EDMI | K11: MK6E | L11: 219150729 | M11: 10.204.30.52 | N11: 4 | O11: 502
A12: Vistec1 | B12: VT1 | C12: X | D12: 1 | E12: Revenue Meter | F12: =B12&"-"&IF(C12="","",C12&"-")&IF(E12="Inverter","INV",IF(E12="Pyranometer","PRY",IF(E12="Revenue Meter","REV",IF(E12="Grid Meter","GMT","recheck"))))&"-"&TEXT(D12,"00") -> VT1-X-REV-01 | G12: Building U(Phase1) Revenue Meter | J12: EDMI | K12: MK6E | L12: 219150735 | M12: 10.204.30.50 | N12: 8 | O12: 502
A13: Vistec1 | B13: VT1 | C13: N | D13: 1 | E13: Revenue Meter | F13: =B13&"-"&IF(C13="","",C13&"-")&IF(E13="Inverter","INV",IF(E13="Pyranometer","PRY",IF(E13="Revenue Meter","REV",IF(E13="Grid Meter","GMT","recheck"))))&"-"&TEXT(D13,"00") -> VT1-N-REV-01 | G13: Building N(Phase1) Revenue Meter | J13: EDMI | K13: MK6E | L13: 219150736 | M13: 10.204.30.55 | N13: 10 | O13: 502
A14: Vistec1 | B14: VT1 | C14: U | D14: 1 | E14: Revenue Meter | F14: =B14&"-"&IF(C14="","",C14&"-")&IF(E14="Inverter","INV",IF(E14="Pyranometer","PRY",IF(E14="Revenue Meter","REV",IF(E14="Grid Meter","GMT","recheck"))))&"-"&TEXT(D14,"00") -> VT1-U-REV-01 | G14: Carpark Buiding X Revenue Meter | J14: EDMI | K14: MK6E | L14: 219150734 | M14: 10.204.30.51 | N14: 9 | O14: 502
A15: Vistec1 | B15: VT1 | C15: V3 | D15: 1 | E15: Grid Meter | F15: =B15&"-"&IF(C15="","",C15&"-")&IF(E15="Inverter","INV",IF(E15="Pyranometer","PRY",IF(E15="Revenue Meter","REV",IF(E15="Grid Meter","GMT","recheck"))))&"-"&TEXT(D15,"00") -> VT1-V3-GMT-01 | G15: V3 Buiding Grid Meter | M15: 10.204.30.81 | N15: 1 | O15: 502
A16: Vistec2 | B16: VT2 | C16: M3 | D16: 1 | E16: Inverter | F16: =B16&"-"&IF(C16="","",C16&"-")&IF(E16="Inverter","INV",IF(E16="Pyranometer","PRY",IF(E16="Revenue Meter","REV",IF(E16="Grid Meter","GMT","recheck"))))&"-"&TEXT(D16,"00") -> VT2-M3-INV-01 | G16: Building M3 Inverter No.1 | H16: 110.88 | I16: kWp | J16: ABB | K16: PVS-100-TL-POWER | M16: 10.204.30.101 | N16: 1 | O16: 502
A17: Vistec2 | B17: VT2 | C17: M3 | D17: 2 | E17: Inverter | F17: =B17&"-"&IF(C17="","",C17&"-")&IF(E17="Inverter","INV",IF(E17="Pyranometer","PRY",IF(E17="Revenue Meter","REV",IF(E17="Grid Meter","GMT","recheck"))))&"-"&TEXT(D17,"00") -> VT2-M3-INV-02 | G17: Building M3 Inverter No.2 | H17: 52.8 | I17: kWp | J17: ABB | K17: PVS-50-TL-SX2 | M17: 10.204.30.102 | N17: 1 | O17: 502
A18: Vistec2 | B18: VT2 | C18: M4 | D18: 1 | E18: Inverter | F18: =B18&"-"&IF(C18="","",C18&"-")&IF(E18="Inverter","INV",IF(E18="Pyranometer","PRY",IF(E18="Revenue Meter","REV",IF(E18="Grid Meter","GMT","recheck"))))&"-"&TEXT(D18,"00") -> VT2-M4-INV-01 | G18: Building M4 Inverter No.1 | H18: 98.12 | I18: kWp | J18: ABB | K18: PVS-100-TL-POWER | M18: 10.204.30.103 | N18: 1 | O18: 502
A19: Vistec2 | B19: VT2 | C19: M4 | D19: 2 | E19: Inverter | F19: =B19&"-"&IF(C19="","",C19&"-")&IF(E19="Inverter","INV",IF(E19="Pyranometer","PRY",IF(E19="Revenue Meter","REV",IF(E19="Grid Meter","GMT","recheck"))))&"-"&TEXT(D19,"00") -> VT2-M4-INV-02 | G19: Building M4 Inverter No.2 | H19: 100.76 | I19: kWp | J19: ABB | K19: PVS-100-TL-POWER | M19: 10.204.30.104 | N19: 1 | O19: 502
A20: Vistec2 | B20: VT2 | C20: N | D20: 1 | E20: Inverter | F20: =B20&"-"&IF(C20="","",C20&"-")&IF(E20="Inverter","INV",IF(E20="Pyranometer","PRY",IF(E20="Revenue Meter","REV",IF(E20="Grid Meter","GMT","recheck"))))&"-"&TEXT(D20,"00") -> VT2-N-INV-01 | G20: Building N(Phase2) Inverter | H20: 66 | I20: kWp | J20: ABB | K20: PVS-50-TL-SX2 | M20: 10.204.30.67 | N20: 1 | O20: 502
A21: Vistec2 | B21: VT2 | C21: U | D21: 1 | E21: Inverter | F21: =B21&"-"&IF(C21="","",C21&"-")&IF(E21="Inverter","INV",IF(E21="Pyranometer","PRY",IF(E21="Revenue Meter","REV",IF(E21="Grid Meter","GMT","recheck"))))&"-"&TEXT(D21,"00") -> VT2-U-INV-01 | G21: Building U(Phase2) Inverter | H21: 95.04 | I21: kWp | J21: ABB | K21: PVS-100-TL-POWER | M21: 10.204.30.68 | N21: 1 | O21: 502
A22: Vistec2 | B22: VT2 | C22: K | D22: 1 | E22: Inverter | F22: =B22&"-"&IF(C22="","",C22&"-")&IF(E22="Inverter","INV",IF(E22="Pyranometer","PRY",IF(E22="Revenue Meter","REV",IF(E22="Grid Meter","GMT","recheck"))))&"-"&TEXT(D22,"00") -> VT2-K-INV-01 | G22: Building K Inverter No.1 | H22: =174.24/2 -> 87.12 | I22: kWp | J22: ABB | K22: PVS-100-TL-POWER | M22: 10.204.30.105 | N22: 1 | O22: 502
A23: Vistec2 | B23: VT2 | C23: K | D23: 2 | E23: Inverter | F23: =B23&"-"&IF(C23="","",C23&"-")&IF(E23="Inverter","INV",IF(E23="Pyranometer","PRY",IF(E23="Revenue Meter","REV",IF(E23="Grid Meter","GMT","recheck"))))&"-"&TEXT(D23,"00") -> VT2-K-INV-02 | G23: Building K Inverter No.2 | H23: =174.24/2 -> 87.12 | I23: kWp | J23: ABB | K23: PVS-100-TL-POWER | M23: 10.204.30.106 | N23: 1 | O23: 502
A24: Vistec2 | B24: VT2 | C24: FT | D24: 1 | E24: Inverter | F24: =B24&"-"&IF(C24="","",C24&"-")&IF(E24="Inverter","INV",IF(E24="Pyranometer","PRY",IF(E24="Revenue Meter","REV",IF(E24="Grid Meter","GMT","recheck"))))&"-"&TEXT(D24,"00") -> VT2-FT-INV-01 | G24: Floating Inverter No.1 | H24: 102.4 | I24: kWp | J24: ABB | K24: PVS-100-TL-POWER | M24: 10.204.30.107 | N24: 1 | O24: 502
A25: Vistec2 | B25: VT2 | C25: CP-M3 | D25: 1 | E25: Inverter | F25: =B25&"-"&IF(C25="","",C25&"-")&IF(E25="Inverter","INV",IF(E25="Pyranometer","PRY",IF(E25="Revenue Meter","REV",IF(E25="Grid Meter","GMT","recheck"))))&"-"&TEXT(D25,"00") -> VT2-CP-M3-INV-01 | G25: Capark M3 Inverter | H25: 23.76 | I25: kWp | J25: ABB | K25: PVS-50-TL-SX2 | M25: 10.204.30.108 | N25: 1 | O25: 502
A26: Vistec2 | B26: VT2 | C26: CP-M3M4 | D26: 1 | E26: Inverter | F26: =B26&"-"&IF(C26="","",C26&"-")&IF(E26="Inverter","INV",IF(E26="Pyranometer","PRY",IF(E26="Revenue Meter","REV",IF(E26="Grid Meter","GMT","recheck"))))&"-"&TEXT(D26,"00") -> VT2-CP-M3M4-INV-01 | G26: Capark M3/M4 Inverter | H26: 60.72 | I26: kWp | J26: Huawei | K26: SUN2000-50KTL-M3 | M26: 10.204.30.110 | N26: 1 | O26: 502
A27: Vistec2 | B27: VT2 | C27: M4 | D27: 1 | E27: Pyranometer | F27: =B27&"-"&IF(C27="","",C27&"-")&IF(E27="Inverter","INV",IF(E27="Pyranometer","PRY",IF(E27="Revenue Meter","REV",IF(E27="Grid Meter","GMT","recheck"))))&"-"&TEXT(D27,"00") -> VT2-M4-PRY-01 | G27: Building M4 Pyranometer | M27: 10.204.30.110 | N27: 6 | O27: 502
A28: Vistec2 | B28: VT2 | C28: M4 | D28: 1 | E28: Revenue Meter | F28: =B28&"-"&IF(C28="","",C28&"-")&IF(E28="Inverter","INV",IF(E28="Pyranometer","PRY",IF(E28="Revenue Meter","REV",IF(E28="Grid Meter","GMT","recheck"))))&"-"&TEXT(D28,"00") -> VT2-M4-REV-01 | G28: Building M4 Revenue Meter | J28: EDMI | K28: MK6E | L28: 219014658 | M28: 10.204.30.59 | N28: 15 | O28: 502
A29: Vistec2 | B29: VT2 | C29: N | D29: 1 | E29: Revenue Meter | F29: =B29&"-"&IF(C29="","",C29&"-")&IF(E29="Inverter","INV",IF(E29="Pyranometer","PRY",IF(E29="Revenue Meter","REV",IF(E29="Grid Meter","GMT","recheck"))))&"-"&TEXT(D29,"00") -> VT2-N-REV-01 | G29: Buiding N(Phase2) Revenue Meter | J29: EDMI | K29: MK6E | L29: 219014662 | M29: 10.204.30.56 | N29: 14 | O29: 502
A30: Vistec2 | B30: VT2 | C30: U | D30: 1 | E30: Revenue Meter | F30: =B30&"-"&IF(C30="","",C30&"-")&IF(E30="Inverter","INV",IF(E30="Pyranometer","PRY",IF(E30="Revenue Meter","REV",IF(E30="Grid Meter","GMT","recheck"))))&"-"&TEXT(D30,"00") -> VT2-U-REV-01 | G30: Buiding U(Phase2) Revenue Meter | J30: EDMI | K30: MK6E | L30: 219014663 | M30: 10.204.30.58 | N30: 13 | O30: 502
A31: KVIS | B31: KVIS | C31: A | D31: 1 | E31: Inverter | F31: =B31&"-"&IF(C31="","",C31&"-")&IF(E31="Inverter","INV",IF(E31="Pyranometer","PRY",IF(E31="Revenue Meter","REV",IF(E31="Grid Meter","GMT","recheck"))))&"-"&TEXT(D31,"00") -> KVIS-A-INV-01 | G31: KVIS Inverter | H31: 105.6 | I31: kWp | J31: ABB | K31: PVS-100-TL-POWER | M31: 10.205.30.100 | N31: 1 | O31: 502
A32: KVIS | B32: KVIS | C32: A | D32: 1 | E32: Revenue Meter | F32: =B32&"-"&IF(C32="","",C32&"-")&IF(E32="Inverter","INV",IF(E32="Pyranometer","PRY",IF(E32="Revenue Meter","REV",IF(E32="Grid Meter","GMT","recheck"))))&"-"&TEXT(D32,"00") -> KVIS-A-REV-01 | G32: KVIS Revenue Meter | J32: EDMI | K32: MK6N | L32: 219014664 | M32: 10.205.30.90 | N32: 19 | O32: 502
A33: KVIS | B33: KVIS | C33: V4 | D33: 1 | E33: Grid Meter | F33: =B33&"-"&IF(C33="","",C33&"-")&IF(E33="Inverter","INV",IF(E33="Pyranometer","PRY",IF(E33="Revenue Meter","REV",IF(E33="Grid Meter","GMT","recheck"))))&"-"&TEXT(D33,"00") -> KVIS-V4-GMT-01 | G33: KVIS Grid Meter | M33: 10.205.30.50 | N33: 1 | O33: 502
A34: Thaioil1 | B34: TO1 | C34: EBC | D34: 1 | E34: Inverter | F34: =B34&"-"&IF(C34="","",C34&"-")&IF(E34="Inverter","INV",IF(E34="Pyranometer","PRY",IF(E34="Revenue Meter","REV",IF(E34="Grid Meter","GMT","recheck"))))&"-"&TEXT(D34,"00") -> TO1-EBC-INV-01 | G34: Inverter No.1 | I34: kWp | J34: Huawei | K34: SUN2000-60KTL-M0 | M34: 192.168.137.10 | N34: 7 | O34: 502
A35: Thaioil1 | B35: TO1 | C35: EBC | D35: 2 | E35: Inverter | F35: =B35&"-"&IF(C35="","",C35&"-")&IF(E35="Inverter","INV",IF(E35="Pyranometer","PRY",IF(E35="Revenue Meter","REV",IF(E35="Grid Meter","GMT","recheck"))))&"-"&TEXT(D35,"00") -> TO1-EBC-INV-02 | G35: Inverter No.2 | I35: kWp | J35: Huawei | K35: SUN2000-60KTL-M0 | M35: 192.168.137.10 | N35: 2 | O35: 502
A36: Thaioil1 | B36: TO1 | C36: EBC | D36: 3 | E36: Inverter | F36: =B36&"-"&IF(C36="","",C36&"-")&IF(E36="Inverter","INV",IF(E36="Pyranometer","PRY",IF(E36="Revenue Meter","REV",IF(E36="Grid Meter","GMT","recheck"))))&"-"&TEXT(D36,"00") -> TO1-EBC-INV-03 | G36: Inverter No.3 | I36: kWp | J36: Huawei | K36: SUN2000-60KTL-M0 | M36: 192.168.137.10 | N36: 4 | O36: 502
A37: Thaioil1 | B37: TO1 | C37: EBC | D37: 4 | E37: Inverter | F37: =B37&"-"&IF(C37="","",C37&"-")&IF(E37="Inverter","INV",IF(E37="Pyranometer","PRY",IF(E37="Revenue Meter","REV",IF(E37="Grid Meter","GMT","recheck"))))&"-"&TEXT(D37,"00") -> TO1-EBC-INV-04 | G37: Inverter No.4 | I37: kWp | J37: Huawei | K37: SUN2000-60KTL-M0 | M37: 192.168.137.10 | N37: 6 | O37: 502
A38: Thaioil1 | B38: TO1 | C38: EBC | D38: 5 | E38: Inverter | F38: =B38&"-"&IF(C38="","",C38&"-")&IF(E38="Inverter","INV",IF(E38="Pyranometer","PRY",IF(E38="Revenue Meter","REV",IF(E38="Grid Meter","GMT","recheck"))))&"-"&TEXT(D38,"00") -> TO1-EBC-INV-05 | G38: Inverter No.5 | I38: kWp | J38: Huawei | K38: SUN2000-60KTL-M0 | M38: 192.168.137.10 | N38: 5 | O38: 502
A39: Thaioil1 | B39: TO1 | C39: EBC | D39: 6 | E39: Inverter | F39: =B39&"-"&IF(C39="","",C39&"-")&IF(E39="Inverter","INV",IF(E39="Pyranometer","PRY",IF(E39="Revenue Meter","REV",IF(E39="Grid Meter","GMT","recheck"))))&"-"&TEXT(D39,"00") -> TO1-EBC-INV-06 | G39: Inverter No.6 | I39: kWp | J39: Huawei | K39: SUN2000-60KTL-M0 | M39: 192.168.137.10 | N39: 3 | O39: 502
A40: Thaioil1 | B40: TO1 | C40: EBC | D40: 7 | E40: Inverter | F40: =B40&"-"&IF(C40="","",C40&"-")&IF(E40="Inverter","INV",IF(E40="Pyranometer","PRY",IF(E40="Revenue Meter","REV",IF(E40="Grid Meter","GMT","recheck"))))&"-"&TEXT(D40,"00") -> TO1-EBC-INV-07 | G40: Inverter No.7 | I40: kWp | J40: Huawei | K40: SUN2000-60KTL-M0 | M40: 192.168.137.10 | N40: 1 | O40: 502
A41: Thaioil1 | B41: TO1 | C41: EBC | D41: 1 | E41: Pyranometer | F41: =B41&"-"&IF(C41="","",C41&"-")&IF(E41="Inverter","INV",IF(E41="Pyranometer","PRY",IF(E41="Revenue Meter","REV",IF(E41="Grid Meter","GMT","recheck"))))&"-"&TEXT(D41,"00") -> TO1-EBC-PRY-01 | G41: Pyranometer | M41: 192.168.137.10 | N41: 12 | O41: 502
...

Sheet PVS100
A1: State | B1: Description | C1: Factor | D1: Register | E1: Data Type | F1: Remark
A2: "not use" | B2: Amps | C2: 1 | D2: 40072 | E2: USHORT
A3: "not use" | B3: Amps PhaseA | C3: 0.1 | D3: 40073 | E3: USHORT
A4: "not use" | B4: Amps PhaseB | C4: 0.1 | D4: 40074 | E4: USHORT
A5: "not use" | B5: Amps PhaseC | C5: 0.1 | D5: 40075 | E5: USHORT
A6: "not use" | B6: A_SF | C6: 1 | D6: 40076 | E6: USHORT
A7: "not use" | B7: Phase Voltage AB | C7: 0.1 | D7: 40077 | E7: USHORT
A8: "not use" | B8: Phase Voltage BC | C8: 0.1 | D8: 40078 | E8: USHORT
A9: "not use" | B9: Phase Voltage CA | C9: 0.1 | D9: 40079 | E9: USHORT
A10: "not use" | B10: Phase Voltage AN | C10: 0.1 | D10: 40080 | E10: USHORT
A11: "not use" | B11: Phase Voltage BN | C11: 0.1 | D11: 40081 | E11: USHORT
A12: "not use" | B12: Phase Voltage CN | C12: 0.1 | D12: 40082 | E12: USHORT
A13: "not use" | B13: V_SF | C13: 1 | D13: 40083 | E13: USHORT
... A36: "not use" | B36: Tmp_SF | C36: 1 | D36: 40107 | E36: SHORT
A37: "use" | B37: Operating State | C37: 1 | D37: 40108 | E37: USHORT | F37: 1: Off 2: Sleeping 3: Starting 4: Normal 5: Throttled(Derating) 6: Shutdown 7: Fault 8: Standby
A38: "not use" | B38: ActWh | C38: 1 | D38: 40187 | E38: FLOAT
A39: "not use" | B39: DC Current_1 | C39: 0.1 | D39: 41123 | E39: USHORT
A40: "not use" | B40: DC Voltage_1 | C40: 0.1 | D40: 41124 | E40: USHORT
A41: "not use" | B41: DC Power_1 | C41: 0.01 | D41: 41125 | E41: USHORT
A42: "not use" | B42: DC Current_2 | C42: 0.1 | D42: 41143 | E42: USHORT
A43: "not use" | B43: DC Voltage_2 | C43: 0.1 | D43: 41144 | E43: USHORT
A44: "not use" | B44: DC Power_2 | C44: 0.01 | D44: 41145 | E44: USHORT
A45: "not use" | B45: DC Current_3 | C45: 0.1 | D45: 41163 | E45: USHORT
A46: "not use" | B46: DC Voltage_3 | C46: 0.1 | D46: 41164 | E46: USHORT
A47: "not use" | B47: DC Power_3 | C47: 0.01 | D47: 41165 | E47: USHORT
A48: "not use" | B48: DC Current_4 | C48: 0.1 | D48: 41183 | E48: USHORT
A49: "not use" | B49: DC Voltage_4 | C49: 0.1 | D49: 41184 | E49: USHORT
... A82: "use" | B82: %Command Watt Limit | C82: 0.1 | D82: 40233 | E82: USHORT

Sheet PVS50
A1: State | B1: Description | C1: Factor | D1: Register | E1: Data Type | F1: Remark
A2: "not use" | B2: Amps | C2: 1 | D2: 40072 | E2: USHORT
A3: "not use" | B3: Amps PhaseA | C3: 0.1 | D3: 40073 | E3: USHORT
A4: "not use" | B4: Amps PhaseB | C4: 0.1 | D4: 40074 | E4: USHORT
A5: "not use" | B5: Amps PhaseC | C5: 0.1 | D5: 40075 | E5: USHORT
A6: "not use" | B6: A_SF | C6: 1 | D6: 40076 | E6: USHORT
A7: "not use" | B7: Phase Voltage AB | C7: 0.1 | D7: 40077 | E7: USHORT
A8: "not use" | B8: Phase Voltage BC | C8: 0.1 | D8: 40078 | E8: USHORT
A9: "not use" | B9: Phase Voltage CA | C9: 0.1 | D9: 40079 | E9: USHORT
A10: "not use" | B10: Phase Voltage AN | C10: 0.1 | D10: 40080 | E10: USHORT
A11: "not use" | B11: Phase Voltage BN | C11: 0.1 | D11: 40081 | E11: USHORT
A12: "not use" | B12: Phase Voltage CN | C12: 0.1 | D12: 40082 | E12: USHORT
A13: "not use" | B13: V_SF | C13: 1 | D13: 40083 | E13: USHORT
... A36: "not use" | B36: Tmp_SF | C36: 1 | D36: 40107 | E36: SHORT
A37: "use" | B37: Operating State | C37: 1 | D37: 40108 | E37: USHORT | F37: 1: Off 2: Sleeping 3: Starting 4: Normal 5: Throttled(Derating) 6: Shutdown 7: Fault 8: Standby
A38: "not use" | B38: ActWh | C38: 1 | D38: 40187 | E38: FLOAT
A39: "not use" | B39: DC Current_1 | C39: 0.1 | D39: 41123 | E39: USHORT
A40: "not use" | B40: DC Voltage_1 | C40: 0.1 | D40: 41124 | E40: USHORT
A41: "not use" | B41: DC Power_1 | C41: 0.01 | D41: 41125 | E41: USHORT
A42: "not use" | B42: DC Current_2 | C42: 0.1 | D42: 41143 | E42: USHORT
A43: "not use" | B43: DC Voltage_2 | C43: 0.1 | D43: 41144 | E43: USHORT
A44: "not use" | B44: DC Power_2 | C44: 0.01 | D44: 41145 | E44: USHORT
A45: "not use" | B45: DC Current_3 | C45: 0.1 | D45: 41163 | E45: USHORT
A46: "not use" | B46: DC Voltage_3 | C46: 0.1 | D46: 41164 | E46: USHORT
A47: "not use" | B47: DC Power_3 | C47: 0.01 | D47: 41165 | E47: USHORT
A48: "not use" | B48: EVENT_1 | C48: 1 | D48: 40110 | E48: LONG
A49: "use" | B49: %Command Watt Limit | C49: 0.1 | D49: 40233 | E49: USHORT

Sheet SUN2000
A1: State | B1: Description | C1: Factor | D1: Register | E1: Data Type | F1: Remark
A2: "use" | B2: Active power | C2: 0.001 | D2: 32080 | E2: SW_INT
A3: "not use" | B3: Active power adjustment | C3: 1 | D3: 40196 | E3: SHORT
A4: "not use" | B4: Cabinet temperature | C4: 0.1 | D4: 32087 | E4: SHORT
A5: "not use" | B5: Collect DSP data | C5: 1 | D5: 32002 | E5: SHORT
A6: "use" | B6: Device status | C6: 1 | D6: 32089 | E6: SHORT | F6: 0x0000 Standby: initializing 0x0001 Standby: detecting insulation resistance 0x0002 Standby: detecting irradiation 0x0003 Standby: Grid detecting 0x0100 Starting 0x0200 On-grid 0x0201 Grid connection: power limited 0x0202 Grid connection: selfderating 0x0300 Shutdown: fault 0x0301 Shutdown: command 0x0302 Shutdown: OVGR 0x0303 Shutdown: communication disconnected 0x0304 Shutdown: power limited 0x0306 Shutdown: DC switches disconnected 0xA000 Standby: no irradiation
A7: "use" | B7: Energy yield of current day | C7: 0.01 | D7: 32114 | E7: SW_UINT
A8: "not use" | B8: Grid frequency | C8: 0.01 | D8: 32085 | E8: SHORT
A9: "not use" | B9: Input power | C9: 0.001 | D9: 32064 | E9: SW_INT
A10: "not use" | B10: Locking | C10: 1 | D10: 40699 | E10: SHORT
A11: "not use" | B11: Phase A current | C11: 0.001 | D11: 32072 | E11: SW_INT
A12: "not use" | B12: Phase A voltage | C12: 0.1 | D12: 32069 | E12: SHORT
A13: "not use" | B13: Phase B current | C13: 0.001 | D13: 32074 | E13: SW_INT
A14: "not use" | B14: Phase B voltage | C14: 0.1 | D14: 32070 | E14: SHORT
A15: "not use" | B15: Phase C current | C15: 0.001 | D15: 32076 | E15: SW_INT
A16: "not use" | B16: Phase C voltage | C16: 0.1 | D16: 32071 | E16: SHORT
A17: "not use" | B17: Power factor | C17: 0.001 | D17: 32084 | E17: SHORT
A18: "not use" | B18: PV1 voltage | C18: 0.1 | D18: 32016 | E18: SHORT
... A72: "use" | B72: Power_adjustment | C72: 0.1 | D72: 35302 | E72: SHORT

Sheet Weather Sensor
A1: State | B1: Description | C1: Factor | D1: Register | E1: Data Type | F1: Remark
A2: "use" | B2: Total_irradiation | C2: 0.1 | D2: 40035 | E2: SHORT
A3: "use" | B3: Daily irradiation amount | C3: 0.1 | D3: 40043 | E3: SW_INT
A4: "use" | B4: Total_irradiation_POA | C4: 0.1 | D4: 40038 | E4: SHORT
A5: "use" | B5: Daily_irradiation_amount_POA | C5: 1 | D5: 40045 | E5: SW_INT

Sheet From LCD
A2: 0000FFFE | B2: A | C2: 0000 | D2: Reg 0000FFFE | E2: Reg 0000FFFE'
A3: 0000F010 | B3: A | C3: 090 | D3: Current Date | E3: 090 Current Date'
A4: 0000F011 | B4: A | C4: 091 | D4: Current Time | E4: 091 Current Time'
A5: 0000FC00 | B5: A | C5: 095 | D5: D/TLast reset | E5: 095D/TLast reset'
A6: 0000F032 | B6: A | C6: 096 | D6: No. of reset | E6: 096 No. of reset'
A7: 0000E033 | B7: A | C7: 093 | D7: Inst. kW | E7: 093 Inst. kW'
A8: 0000E043 | B8: A | C8: 193 | D8: Inst. kVAr | E8: 193 Inst. kVAr'
A9: 00000069 | B9: A | C9: 000 | D9: 000 Total kWh | E9: '000 Total kWh'
A10: 00000060 | B10: A | C10: 001 | D10: kWh Rate A | E10: 001 kWh Rate A'
A11: 00000061 | B11: A | C11: 002 | D11: kWh Rate B | E11: 002 kWh Rate B'
A12: 00000062 | B12: A | C12: 003 | D12: kWh Rate C | E12: 003 kWh Rate C'
A13: 00001000 | B13: A | C13: 005 | D13: Max kW A | E13: 005 Max kW A'
... A28: 00001142 | B28: A | C28: 117 | D28: kVAr-Cum C | E28: 117 kVAr-Cum C'
A29: 0000F540 | B29: B | D29: CT Ratio | E29: CT Ratio'
A30: 0000F541 | B30: B | D30: VT Ratio | E30: VT Ratio'
A31: 0000F00A | B31: B | D31: Measurement Meth | E31: Measurement Meth'
A32: 0000F500 | B32: B | D32: ABC_V+ABC_A | E32: ABC_V+ABC_A'
A33: 0000E020 | B33: B | D33: V I Angle PhA | E33: V I Angle PhA'
A34: 0000E021 | B34: B | D34: V I Angle PhB | E34: V I Angle PhB'
A35: 0000E022 | B35: B | D35: V I Angle PhC | E35: V I Angle PhC'
A36: 0000E026 | B36: B | D36: Power Factor | E36: Power Factor'
A37: 0000E060 | B37: B | D37: Frequency | E37: Frequency'
A38: 0000FC20 | B38: B | C38: 192 | D38: LastPowerDown | E38: 192LastPowerDown'
A39: 0000F093 | B39: B | C39: 292 | D39: Last Power Up | E39: 292Last Power Up'
A40: 0000FFFE | B40: C | C40: 0000 | D40: Reg 0000FFFE | E40: Reg 0000FFFE'
A41: 0000F010 | B41: C | C41: 090 | D41: Current Date | E41: 090 Current Date'
A42: 0000F011 | B42: C | C42: 091 | D42: Current Time | E42: 091 Current Time'
A43: 0000FC00 | B43: C | C43: 095 | D43: D/T Last rese | E43: 095D/T Last rese'
A44: 0000F032 | B44: C | C44: 096 | D44: No. of Reset | E44: 096 No. of Reset'
A45: 00000049 | B45: C | C45: 111 | D45: BT Total kWh | E45: 111 BT Total kWh'
A46: 00000040 | B46: C | C46: 010 | D46: 010 BT kWh A | E46: '010 BT kWh A'
A47: 00000041 | B47: C | C47: 020 | D47: BT kWh B | E47: 020 BT kWh B'
A48: 00000042 | B48: C | C48: 030 | D48: 030 BT kWh C | E48: '030 BT kWh C'
A49: 00001020 | B49: C | C49: 050 | D49: PV kW A | E49: 050 PV kW A'
... A57: 00001149 | B57: C | C57: 118 | D57: kVAr-Cum | E57: 118 kVAr-Cum'
A58: 0000F016 | B58: B | D58: Current Status F | E58: Current Status F'
A59: 0000F017 | B59: B | D59: Latched Status F | E59: Latched Status F'

Sheet Bill Point
A1: ID | B1: Previous value displayed in Section C | C1: Register | D1: AI
A2: 888 | B2: Previous LCD Checking | E2: 0000FFFE
A3: 90 | B3: Previous DD-MM-YY of Reading | C3: 0000F010 | E3: 0000F010
A4: 91 | B4: Previous Time of Reading | C4: 0000F011 | E4: 0000F011
A5: 95 | B5: Previous DD-MM-YY : Time of Reset | C5: 0000FC00 | E5: 0000FC00
A6: 96 | B6: PreviousTimes of Reset | C6: 0000F032 | E6: 0000F032
A7: 111 | B7: Previous kWh Total Reading(Reset) | C7: 00000049 | E7: 00000049
A8: 10 | B8: Previous kWh Rate A Reading(Reset) | C8: 00000040 | E8: 00000040
A9: 20 | B9: Previous kWh Rate B Reading(Reset) | C9: 00000041 | E9: 00000041
A10: 30 | B10: Previous kWh Rate C Reading(Reset) | C10: 00000042 | E10: 00000042
A11: 50 | B11: Previous kWp Rate A Reading(Reset) | C11: 00001020 | E11: 00001020
A12: 60 | B12: Previous kWp Rate B Reading(Reset) | C12: 00001021 | E12: 00001021
A13: 70 | B13: Previous kWp Rate C Reading(Reset) | C13: 00001022 | E13: 00001022
A14: 15 | B14: Previous Comulative kWh-Rate A Reading | C14: 00001040 | E14: 00001040
... A19: 118 | B19: Previous Comulative kVarh demand Total Reading(Reset) | C19: 00001149 | E19: 00001149

Sheet VISTEC12 (2)
A1: VT1 | B1: VT2 | C1: VT3 | D1: MODBUS VISTEC1&2&KVIS | K1: ENOS KVIS | W1: ENOS VISTEC
A2: =VLOOKUP(G2,$U$2:$AF$93,2,0) -> Used | B2: =VLOOKUP(G2,$U$2:$AF$93,2,0) -> Used | C2: =VLOOKUP(G2,$I$2:$T$93,2,0) -> Used | D2: 7001 | E2: 0000E033 | F2: Inst kW | G2: =D2-1 -> 7000 | I2: =R2 -> 7000 | J2: Used | K2: Inst_kW | L2: 0 | M2: float | N2: AI | O2: 0.001 | P2: 0 | Q2: Inst_kW | R2: 7000 | S2: 3 | T2: FLOAT | U2: =AD2 -> 7000 | V2: Used | W2: Inst_kW | X2: 0 | Y2: float | Z2: AI | AA2: 0.001 | AB2: 0 | AC2: Inst_kW | AD2: 7000 | AE2: 3 | AF2: FLOAT
A3: =VLOOKUP(G3,$U$2:$AF$93,2,0) -> Used | B3: =VLOOKUP(G3,$U$2:$AF$93,2,0) -> Used | C3: =VLOOKUP(G3,$I$2:$T$93,2,0) -> Used | D3: 7003 | E3: 0000E043 | F3: Inst kVAr | G3: =D3-1 -> 7002 | I3: =R3 -> 7002 | J3: Used | K3: Inst_kVAr | L3: 1 | M3: float | N3: AI | O3: 0.001 | P3: 0 | Q3: Inst_kVAr | R3: 7002 | S3: 3 | T3: FLOAT | U3: =AD3 -> 7002 | V3: Used | W3: Inst_kVAr | X3: 1 | Y3: float | Z3: AI | AA3: 0.001 | AB3: 0 | AC3: Inst_kVAr | AD3: 7002 | AE3: 3 | AF3: FLOAT
A4: =VLOOKUP(G4,$U$2:$AF$93,2,0) -> Used | B4: =VLOOKUP(G4,$U$2:$AF$93,2,0) -> Used | C4: =VLOOKUP(G4,$I$2:$T$93,2,0) -> Used | D4: 7005 | E4: 00000069 | F4: Ex Total kWh | G4: =D4-1 -> 7004 | I4: =R4 -> 7004 | J4: Used | K4: Ex_Total_kWh | L4: 2 | M4: float | N4: AI | O4: 0.001 | P4: 0 | Q4: Ex_Total_kWh | R4: 7004 | S4: 3 | T4: FLOAT | U4: =AD4 -> 7004 | V4: Used | W4: Ex_Total_kWh | X4: 2 | Y4: float | Z4: AI | AA4: 0.001 | AB4: 0 | AC4: Ex_Total_kWh | AD4: 7004 | AE4: 3 | AF4: FLOAT
A5: =VLOOKUP(G5,$U$2:$AF$93,2,0) -> Used | B5: =VLOOKUP(G5,$U$2:$AF$93,2,0) -> Used | C5: =VLOOKUP(G5,$I$2:$T$93,2,0) -> Used | D5: 7007 | E5: 00000000 | F5: Ex kWh RateA | G5: =D5-1 -> 7006 | I5: =R5 -> 7006 | J5: Used | K5: Ex_kWh_RateA | L5: 3 | M5: float | N5: AI | O5: 0.001 | P5: 0 | Q5: Ex_kWh_RateA | R5: 7006 | S5: 3 | T5: FLOAT | U5: =AD5 -> 7006 | V5: Used | W5: Ex_kWh_RateA | X5: 3 | Y5: float | Z5: AI | AA5: 0.001 | AB5: 0 | AC5: Ex_kWh_RateA | AD5: 7006 | AE5: 3 | AF5: FLOAT
A6: =VLOOKUP(G6,$U$2:$AF$93,2,0) -> Used | B6: =VLOOKUP(G6,$U$2:$AF$93,2,0) -> Used | C6: =VLOOKUP(G6,$I$2:$T$93,2,0) -> Used | D6: 7009 | E6: 00000001 | F6: Ex kWh RateB | G6: =D6-1 -> 7008 | I6: =R6 -> 7008 | J6: Used | K6: Ex_kWh_RateB | L6: 4 | M6: float | N6: AI | O6: 0.001 | P6: 0 | Q6: Ex_kWh_RateB | R6: 7008 | S6: 3 | T6: FLOAT | U6: =AD6 -> 7008 | V6: Used | W6: Ex_kWh_RateB | X6: 4 | Y6: float | Z6: AI | AA6: 0.001 | AB6: 0 | AC6: Ex_kWh_RateB | AD6: 7008 | AE6: 3 | AF6: FLOAT
A7: =VLOOKUP(G7,$U$2:$AF$93,2,0) -> Used | B7: =VLOOKUP(G7,$U$2:$AF$93,2,0) -> Used | C7: =VLOOKUP(G7,$I$2:$T$93,2,0) -> Used | D7: 7011 | E7: 00000002 | F7: Ex kWh RateC | G7: =D7-1 -> 7010 | I7: =R7 -> 7010 | J7: Used | K7: Ex_kWh_RateC | L7: 5 | M7: float | N7: AI | O7: 0.001 | P7: 0 | Q7: Ex_kWh_RateC | R7: 7010 | S7: 3 | T7: FLOAT | U7: =AD7 -> 7010 | V7: Used | W7: Ex_kWh_RateC | X7: 5 | Y7: float | Z7: AI | AA7: 0.001 | AB7: 0 | AC7: Ex_kWh_RateC | AD7: 7010 | AE7: 3 | AF7: FLOAT
A8: =VLOOKUP(G8,$U$2:$AF$93,2,0) -> 0 | B8: =VLOOKUP(G8,$U$2:$AF$93,2,0) -> 0 | C8: =VLOOKUP(G8,$I$2:$T$93,2,0) -> 0 | D8: 7013 | E8: 00001000 | F8: Ex Max kW A | G8: =D8-1 -> 7012 | I8: =R8 -> 7012 | K8: Ex_Max_kW_A | L8: 6 | M8: float | N8: AI | O8: 0.001 | P8: 0 | Q8: Ex_Max_kW_A | R8: 7012 | S8: 3 | T8: FLOAT | U8: =AD8 -> 7012 | W8: Ex_Max_kW_A | X8: 6 | Y8: float | Z8: AI | AA8: 0.001 | AB8: 0 | AC8: Ex_Max_kW_A | AD8: 7012 | AE8: 3 | AF8: FLOAT
A9: =VLOOKUP(G9,$U$2:$AF$93,2,0) -> 0 | B9: =VLOOKUP(G9,$U$2:$AF$93,2,0) -> 0 | C9: =VLOOKUP(G9,$I$2:$T$93,2,0) -> 0 | D9: 7015 | E9: 00001001 | F9: Ex Max kW B | G9: =D9-1 -> 7014 | I9: =R9 -> 7014 | K9: Ex_Max_kW_B | L9: 7 | M9: float | N9: AI | O9: 0.001 | P9: 0 | Q9: Ex_Max_kW_B | R9: 7014 | S9: 3 | T9: FLOAT | U9: =AD9 -> 7014 | W9: Ex_Max_kW_B | X9: 7 | Y9: float | Z9: AI | AA9: 0.001 | AB9: 0 | AC9: Ex_Max_kW_B | AD9: 7014 | AE9: 3 | AF9: FLOAT
A10: =VLOOKUP(G10,$U$2:$AF$93,2,0) -> 0 | B10: =VLOOKUP(G10,$U$2:$AF$93,2,0) -> 0 | C10: =VLOOKUP(G10,$I$2:$T$93,2,0) -> 0 | D10: 7017 | E10: 00001002 | F10: Ex Max kW C | G10: =D10-1 -> 7016 | I10: =R10 -> 7016 | K10: Ex_Max_kW_C | L10: 8 | M10: float | N10: AI | O10: 0.001 | P10: 0 | Q10: Ex_Max_kW_C | R10: 7016 | S10: 3 | T10: FLOAT | U10: =AD10 -> 7016 | W10: Ex_Max_kW_C | X10: 8 | Y10: float | Z10: AI | AA10: 0.001 | AB10: 0 | AC10: Ex_Max_kW_C | AD10: 7016 | AE10: 3 | AF10: FLOAT
A11: =VLOOKUP(G11,$U$2:$AF$93,2,0) -> 0 | B11: =VLOOKUP(G11,$U$2:$AF$93,2,0) -> 0 | C11: =VLOOKUP(G11,$I$2:$T$93,2,0) -> 0 | D11: 7019 | E11: 00001040 | F11: Ex kW-Cum A | G11: =D11-1 -> 7018 | I11: =R11 -> 7018 | K11: Ex_kW_Cum_A | L11: 9 | M11: float | N11: AI | O11: 0.001 | P11: 0 | Q11: Ex_kW_Cum_A | R11: 7018 | S11: 3 | T11: FLOAT | U11: =AD11 -> 7018 | W11: Ex_kW_Cum_A | X11: 9 | Y11: float | Z11: AI | AA11: 0.001 | AB11: 0 | AC11: Ex_kW_Cum_A | AD11: 7018 | AE11: 3 | AF11: FLOAT
A12: =VLOOKUP(G12,$U$2:$AF$93,2,0) -> 0 | B12: =VLOOKUP(G12,$U$2:$AF$93,2,0) -> 0 | C12: =VLOOKUP(G12,$I$2:$T$93,2,0) -> 0 | D12: 7021 | E12: 00001041 | F12: Ex kW-Cum B | G12: =D12-1 -> 7020 | I12: =R12 -> 7020 | K12: Ex_kW_Cum_B | L12: 10 | M12: float | N12: AI | O12: 0.001 | P12: 0 | Q12: Ex_kW_Cum_B | R12: 7020 | S12: 3 | T12: FLOAT | U12: =AD12 -> 7020 | W12: Ex_kW_Cum_B | X12: 10 | Y12: float | Z12: AI | AA12: 0.001 | AB12: 0 | AC12: Ex_kW_Cum_B | AD12: 7020 | AE12: 3 | AF12: FLOAT
A13: =VLOOKUP(G13,$U$2:$AF$93,2,0) -> 0 | B13: =VLOOKUP(G13,$U$2:$AF$93,2,0) -> 0 | C13: =VLOOKUP(G13,$I$2:$T$93,2,0) -> 0 | D13: 7023 | E13: 00001042 | F13: Ex kW-Cum C | G13: =D13-1 -> 7022 | I13: =R13 -> 7022 | K13: Ex_kW_Cum_C | L13: 11 | M13: float | N13: AI | O13: 0.001 | P13: 0 | Q13: Ex_kW_Cum_C | R13: 7022 | S13: 3 | T13: FLOAT | U13: =AD13 -> 7022 | W13: Ex_kW_Cum_C | X13: 11 | Y13: float | Z13: AI | AA13: 0.001 | AB13: 0 | AC13: Ex_kW_Cum_C | AD13: 7022 | AE13: 3 | AF13: FLOAT
A14: =VLOOKUP(G14,$U$2:$AF$93,2,0) -> Used | B14: =VLOOKUP(G14,$U$2:$AF$93,2,0) -> Used | C14: =VLOOKUP(G14,$I$2:$T$93,2,0) -> Used | D14: 7025 | E14: 00000169 | F14: Ex Total kVArh | G14: =D14-1 -> 7024 | I14: =R14 -> 7024 | J14: Used | K14: Ex_Total_kVArh | L14: 12 | M14: float | N14: AI | O14: 0.001 | P14: 0 | Q14: Ex_Total_kVArh | R14: 7024 | S14: 3 | T14: FLOAT | U14: =AD14 -> 7024 | V14: Used | W14: Ex_Total_kVArh | X14: 12 | Y14: float | Z14: AI | AA14: 0.001 | AB14: 0 | AC14: Ex_Total_kVArh | AD14: 7024 | AE14: 3 | AF14: FLOAT
A15: =VLOOKUP(G15,$U$2:$AF$93,2,0) -> 0 | B15: =VLOOKUP(G15,$U$2:$AF$93,2,0) -> 0 | C15: =VLOOKUP(G15,$I$2:$T$93,2,0) -> 0 | D15: 7027 | E15: 00000160 | F15: Ex kVArh A | G15: =D15-1 -> 7026 | I15: =R15 -> 7026 | K15: Ex_kVArh_RateA | L15: 13 | M15: float | N15: AI | O15: 0.001 | P15: 0 | Q15: Ex_kVArh_RateA | R15: 7026 | S15: 3 | T15: FLOAT | U15: =AD15 -> 7026 | W15: Ex_kVArh_RateA | X15: 13 | Y15: float | Z15: AI | AA15: 0.001 | AB15: 0 | AC15: Ex_kVArh_RateA | AD15: 7026 | AE15: 3 | AF15: FLOAT
A16: =VLOOKUP(G16,$U$2:$AF$93,2,0) -> 0 | B16: =VLOOKUP(G16,$U$2:$AF$93,2,0) -> 0 | C16: =VLOOKUP(G16,$I$2:$T$93,2,0) -> 0 | D16: 7029 | E16: 00000161 | F16: Ex kVArh B | G16: =D16-1 -> 7028 | I16: =R16 -> 7028 | K16: Ex_kVArh_RateB | L16: 14 | M16: float | N16: AI | O16: 0.001 | P16: 0 | Q16: Ex_kVArh_RateB | R16: 7028 | S16: 3 | T16: FLOAT | U16: =AD16 -> 7028 | W16: Ex_kVArh_RateB | X16: 14 | Y16: float | Z16: AI | AA16: 0.001 | AB16: 0 | AC16: Ex_kVArh_RateB | AD16: 7028 | AE16: 3 | AF16: FLOAT
A17: =VLOOKUP(G17,$U$2:$AF$93,2,0) -> 0 | B17: =VLOOKUP(G17,$U$2:$AF$93,2,0) -> 0 | C17: =VLOOKUP(G17,$I$2:$T$93,2,0) -> 0 | D17: 7031 | E17: 00000162 | F17: Ex kVArh C | G17: =D17-1 -> 7030 | I17: =R17 -> 7030 | K17: Ex_kVArh_RateC | L17: 15 | M17: float | N17: AI | O17: 0.001 | P17: 0 | Q17: Ex_kVArh_RateC | R17: 7030 | S17: 3 | T17: FLOAT | U17: =AD17 -> 7030 | W17: Ex_kVArh_RateC | X17: 15 | Y17: float | Z17: AI | AA17: 0.001 | AB17: 0 | AC17: Ex_kVArh_RateC | AD17: 7030 | AE17: 3 | AF17: FLOAT
A18: =VLOOKUP(G18,$U$2:$AF$93,2,0) -> 0 | B18: =VLOOKUP(G18,$U$2:$AF$93,2,0) -> 0 | C18: =VLOOKUP(G18,$I$2:$T$93,2,0) -> 0 | D18: 7033 | E18: 00001100 | F18: Ex Max kVArh A | G18: =D18-1 -> 7032 | I18: =R18 -> 7032 | K18: Ex_Max_kVAr_A | L18: 16 | M18: float | N18: AI | O18: 0.001 | P18: 0 | Q18: Ex_Max_kVAr_A | R18: 7032 | S18: 3 | T18: FLOAT | U18: =AD18 -> 7032 | W18: Ex_Max_kVAr_A | X18: 16 | Y18: float | Z18: AI | AA18: 0.001 | AB18: 0 | AC18: Ex_Max_kVAr_A | AD18: 7032 | AE18: 3 | AF18: FLOAT
A19: =VLOOKUP(G19,$U$2:$AF$93,2,0) -> 0 | B19: =VLOOKUP(G19,$U$2:$AF$93,2,0) -> 0 | C19: =VLOOKUP(G19,$I$2:$T$93,2,0) -> 0 | D19: 7035 | E19: 00001101 | F19: Ex Max kVArh B | G19: =D19-1 -> 7034 | I19: =R19 -> 7034 | K19: Ex_Max_kVAr_B | L19: 17 | M19: float | N19: AI | O19: 0.001 | P19: 0 | Q19: Ex_Max_kVAr_B | R19: 7034 | S19: 3 | T19: FLOAT | U19: =AD19 -> 7034 | W19: Ex_Max_kVAr_B | X19: 17 | Y19: float | Z19: AI | AA19: 0.001 | AB19: 0 | AC19: Ex_Max_kVAr_B | AD19: 7034 | AE19: 3 | AF19: FLOAT
A20: =VLOOKUP(G20,$U$2:$AF$93,2,0) -> 0 | B20: =VLOOKUP(G20,$U$2:$AF$93,2,0) -> 0 | C20: =VLOOKUP(G20,$I$2:$T$93,2,0) -> 0 | D20: 7037 | E20: 00001102 | F20: Ex Max kVArh C | G20: =D20-1 -> 7036 | I20: =R20 -> 7036 | K20: Ex_Max_kVAr_C | L20: 18 | M20: float | N20: AI | O20: 0.001 | P20: 0 | Q20: Ex_Max_kVAr_C | R20: 7036 | S20: 3 | T20: FLOAT | U20: =AD20 -> 7036 | W20: Ex_Max_kVAr_C | X20: 18 | Y20: float | Z20: AI | AA20: 0.001 | AB20: 0 | AC20: Ex_Max_kVAr_C | AD20: 7036 | AE20: 3 | AF20: FLOAT
A21: =VLOOKUP(G21,$U$2:$AF$93,2,0) -> 0 | B21: =VLOOKUP(G21,$U$2:$AF$93,2,0) -> 0 | C21: =VLOOKUP(G21,$I$2:$T$93,2,0) -> 0 | D21: 7039 | E21: 00000140 | F21: Ex kVArh-Cum A | G21: =D21-1 -> 7038 | I21: =R21 -> 7038 | K21: Ex_kVAr_Cum_A | L21: 19 | M21: float | N21: AI | O21: 0.001 | P21: 0 | Q21: Ex_kVAr_Cum_A | R21: 7038 | S21: 3 | T21: FLOAT | U21: =AD21 -> 7038 | W21: Ex_kVAr_Cum_A | X21: 19 | Y21: float | Z21: AI | AA21: 0.001 | AB21: 0 | AC21: Ex_kVAr_Cum_A | AD21: 7038 | AE21: 3 | AF21: FLOAT
A22: =VLOOKUP(G22,$U$2:$AF$93,2,0) -> 0 | B22: =VLOOKUP(G22,$U$2:$AF$93,2,0) -> 0 | C22: =VLOOKUP(G22,$I$2:$T$93,2,0) -> 0 | D22: 7041 | E22: 00000141 | F22: Ex kVArh-Cum B | G22: =D22-1 -> 7040 | I22: =R22 -> 7040 | K22: Ex_kVAr_Cum_B | L22: 20 | M22: float | N22: AI | O22: 0.001 | P22: 0 | Q22: Ex_kVAr_Cum_B | R22: 7040 | S22: 3 | T22: FLOAT | U22: =AD22 -> 7040 | W22: Ex_kVAr_Cum_B | X22: 20 | Y22: float | Z22: AI | AA22: 0.001 | AB22: 0 | AC22: Ex_kVAr_Cum_B | AD22: 7040 | AE22: 3 | AF22: FLOAT
A23: =VLOOKUP(G23,$U$2:$AF$93,2,0) -> 0 | B23: =VLOOKUP(G23,$U$2:$AF$93,2,0) -> 0 | C23: =VLOOKUP(G23,$I$2:$T$93,2,0) -> 0 | D23: 7043 | E23: 00000142 | F23: Ex kVArh-Cum C | G23: =D23-1 -> 7042 | I23: =R23 -> 7042 | K23: Ex_kVAr_Cum_C | L23: 21 | M23: float | N23: AI | O23: 0.001 | P23: 0 | Q23: Ex_kVAr_Cum_C | R23: 7042 | S23: 3 | T23: FLOAT | U23: =AD23 -> 7042 | W23: Ex_kVAr_Cum_C | X23: 21 | Y23: float | Z23: AI | AA23: 0.001 | AB23: 0 | AC23: Ex_kVAr_Cum_C | AD23: 7042 | AE23: 3 | AF23: FLOAT
A24: =VLOOKUP(G24,$U$2:$AF$93,2,0) -> Used | B24: =VLOOKUP(G24,$U$2:$AF$93,2,0) -> Used | C24: =VLOOKUP(G24,$I$2:$T$93,2,0) -> Used | D24: 7045 | E24: 00000049 | F24: Ex BT Total kWh | G24: =D24-1 -> 7044 | I24: =R24 -> 7044 | J24: Used | K24: Ex_BT_Total_kWh | L24: 22 | M24: float | N24: AI | O24: 0.001 | P24: 0 | Q24: Ex_BT_Total_kWh | R24: 7044 | S24: 3 | T24: FLOAT | U24: =AD24 -> 7044 | V24: Used | W24: Ex_BT_Total_kWh | X24: 22 | Y24: float | Z24: AI | AA24: 0.001 | AB24: 0 | AC24: Ex_BT_Total_kWh | AD24: 7044 | AE24: 3 | AF24: FLOAT
A25: =VLOOKUP(G25,$U$2:$AF$93,2,0) -> Used | B25: =VLOOKUP(G25,$U$2:$AF$93,2,0) -> Used | C25: =VLOOKUP(G25,$I$2:$T$93,2,0) -> Used | D25: 7047 | E25: 00000040 | F25: Ex BT kWhA | G25: =D25-1 -> 7046 | I25: =R25 -> 7046 | J25: Used | K25: Ex_BT_kWhA | L25: 23 | M25: float | N25: AI | O25: 0.001 | P25: 0 | Q25: Ex_BT_kWhA | R25: 7046 | S25: 3 | T25: FLOAT | U25: =AD25 -> 7046 | V25: Used | W25: Ex_BT_kWhA | X25: 23 | Y25: float | Z25: AI | AA25: 0.001 | AB25: 0 | AC25: Ex_BT_kWhA | AD25: 7046 | AE25: 3 | AF25: FLOAT
A26: =VLOOKUP(G26,$U$2:$AF$93,2,0) -> Used | B26: =VLOOKUP(G26,$U$2:$AF$93,2,0) -> Used | C26: =VLOOKUP(G26,$I$2:$T$93,2,0) -> Used | D26: 7049 | E26: 00000041 | F26: Ex BT kWhB | G26: =D26-1 -> 7048 | I26: =R26 -> 7048 | J26: Used | K26: Ex_BT_kWhB | L26: 24 | M26: float | N26: AI | O26: 0.001 | P26: 0 | Q26: Ex_BT_kWhB | R26: 7048 | S26: 3 | T26: FLOAT | U26: =AD26 -> 7048 | V26: Used | W26: Ex_BT_kWhB | X26: 24 | Y26: float | Z26: AI | AA26: 0.001 | AB26: 0 | AC26: Ex_BT_kWhB | AD26: 7048 | AE26: 3 | AF26: FLOAT
A27: =VLOOKUP(G27,$U$2:$AF$93,2,0) -> Used | B27: =VLOOKUP(G27,$U$2:$AF$93,2,0) -> Used | C27: =VLOOKUP(G27,$I$2:$T$93,2,0) -> Used | D27: 7051 | E27: 00000042 | F27: Ex BT kWhC | G27: =D27-1 -> 7050 | I27: =R27 -> 7050 | J27: Used | K27: Ex_BT_kWhC | L27: 25 | M27: float | N27: AI | O27: 0.001 | P27: 0 | Q27: Ex_BT_kWhC | R27: 7050 | S27: 3 | T27: FLOAT | U27: =AD27 -> 7050 | V27: Used | W27: Ex_BT_kWhC | X27: 25 | Y27: float | Z27: AI | AA27: 0.001 | AB27: 0 | AC27: Ex_BT_kWhC | AD27: 7050 | AE27: 3 | AF27: FLOAT
A28: =VLOOKUP(G28,$U$2:$AF$93,2,0) -> 0 | B28: =VLOOKUP(G28,$U$2:$AF$93,2,0) -> 0 | C28: =VLOOKUP(G28,$I$2:$T$93,2,0) -> 0 | D28: 7053 | E28: 00001020 | F28: Ex PV kW A | G28: =D28-1 -> 7052 | I28: =R28 -> 7052 | K28: Ex_PV_kW_A | L28: 26 | M28: float | N28: AI | O28: 0.001 | P28: 0 | Q28: Ex_PV_kW_A | R28: 7052 | S28: 3 | T28: FLOAT | U28: =AD28 -> 7052 | W28: Ex_PV_kW_A | X28: 26 | Y28: float | Z28: AI | AA28: 0.001 | AB28: 0 | AC28: Ex_PV_kW_A | AD28: 7052 | AE28: 3 | AF28: FLOAT
A29: =VLOOKUP(G29,$U$2:$AF$93,2,0) -> 0 | B29: =VLOOKUP(G29,$U$2:$AF$93,2,0) -> 0 | C29: =VLOOKUP(G29,$I$2:$T$93,2,0) -> 0 | D29: 7055 | E29: 00001021 | F29: Ex PV kW B | G29: =D29-1 -> 7054 | I29: =R29 -> 7054 | K29: Ex_PV_kW_B | L29: 27 | M29: float | N29: AI | O29: 0.001 | P29: 0 | Q29: Ex_PV_kW_B | R29: 7054 | S29: 3 | T29: FLOAT | U29: =AD29 -> 7054 | W29: Ex_PV_kW_B | X29: 27 | Y29: float | Z29: AI | AA29: 0.001 | AB29: 0 | AC29: Ex_PV_kW_B | AD29: 7054 | AE29: 3 | AF29: FLOAT
A30: =VLOOKUP(G30,$U$2:$AF$93,2,0) -> 0 | B30: =VLOOKUP(G30,$U$2:$AF$93,2,0) -> 0 | C30: =VLOOKUP(G30,$I$2:$T$93,2,0) -> 0 | D30: 7057 | E30: 00001022 | F30: Ex PV kW C | G30: =D30-1 -> 7056 | I30: =R30 -> 7056 | K30: Ex_PV_kW_C | L30: 28 | M30: float | N30: AI | O30: 0.001 | P30: 0 | Q30: Ex_PV_kW_C | R30: 7056 | S30: 3 | T30: FLOAT | U30: =AD30 -> 7056 | W30: Ex_PV_kW_C | X30: 28 | Y30: float | Z30: AI | AA30: 0.001 | AB30: 0 | AC30: Ex_PV_kW_C | AD30: 7056 | AE30: 3 | AF30: FLOAT
A31: =VLOOKUP(G31,$U$2:$AF$93,2,0) -> Used | B31: =VLOOKUP(G31,$U$2:$AF$93,2,0) -> Used | C31: =VLOOKUP(G31,$I$2:$T$93,2,0) -> Used | D31: 7059 | E31: 00001040 | F31: Ex kW-Cum A | G31: =D31-1 -> 7058 | I31: =R31 -> 7058 | J31: Used | K31: Ex_kW_Cum_A2 | L31: 29 | M31: float | N31: AI | O31: 0.001 | P31: 0 | Q31: Ex_kW_Cum_A2 | R31: 7058 | S31: 3 | T31: FLOAT | U31: =AD31 -> 7058 | V31: Used | W31: Ex_kW_Cum_A2 | X31: 29 | Y31: float | Z31: AI | AA31: 0.001 | AB31: 0 | AC31: Ex_kW_Cum_A2 | AD31: 7058 | AE31: 3 | AF31: FLOAT
A32: =VLOOKUP(G32,$U$2:$AF$93,2,0) -> Used | B32: =VLOOKUP(G32,$U$2:$AF$93,2,0) -> Used | C32: =VLOOKUP(G32,$I$2:$T$93,2,0) -> Used | D32: 7061 | E32: 00001041 | F32: Ex kW-Cum B | G32: =D32-1 -> 7060 | I32: =R32 -> 7060 | J32: Used | K32: Ex_kW_Cum_B2 | L32: 30 | M32: float | N32: AI | O32: 0.001 | P32: 0 | Q32: Ex_kW_Cum_B2 | R32: 7060 | S32: 3 | T32: FLOAT | U32: =AD32 -> 7060 | V32: Used | W32: Ex_kW_Cum_B2 | X32: 30 | Y32: float | Z32: AI | AA32: 0.001 | AB32: 0 | AC32: Ex_kW_Cum_B2 | AD32: 7060 | AE32: 3 | AF32: FLOAT
A33: =VLOOKUP(G33,$U$2:$AF$93,2,0) -> Used | B33: =VLOOKUP(G33,$U$2:$AF$93,2,0) -> Used | C33: =VLOOKUP(G33,$I$2:$T$93,2,0) -> Used | D33: 7063 | E33: 00001042 | F33: Ex kW-Cum C | G33: =D33-1 -> 7062 | I33: =R33 -> 7062 | J33: Used | K33: Ex_kW_Cum_C2 | L33: 31 | M33: float | N33: AI | O33: 0.001 | P33: 0 | Q33: Ex_kW_Cum_C2 | R33: 7062 | S33: 3 | T33: FLOAT | U33: =AD33 -> 7062 | V33: Used | W33: Ex_kW_Cum_C2 | X33: 31 | Y33: float | Z33: AI | AA33: 0.001 | AB33: 0 | AC33: Ex_kW_Cum_C2 | AD33: 7062 | AE33: 3 | AF33: FLOAT
A34: =VLOOKUP(G34,$U$2:$AF$93,2,0) -> Used | B34: =VLOOKUP(G34,$U$2:$AF$93,2,0) -> Used | C34: =VLOOKUP(G34,$I$2:$T$93,2,0) -> Used | D34: 7065 | E34: 00000149 | F34: Ex BT Total kVA | G34: =D34-1 -> 7064 | I34: =R34 -> 7064 | J34: Used | K34: Ex_BT_Total_kVAr | L34: 32 | M34: float | N34: AI | O34: 0.001 | P34: 0 | Q34: Ex_BT_Total_kVAr | R34: 7064 | S34: 3 | T34: FLOAT | U34: =AD34 -> 7064 | V34: Used | W34: Ex_BT_Total_kVAr | X34: 32 | Y34: float | Z34: AI | AA34: 0.001 | AB34: 0 | AC34: Ex_BT_Total_kVAr | AD34: 7064 | AE34: 3 | AF34: FLOAT
A35: =VLOOKUP(G35,$U$2:$AF$93,2,0) -> 0 | B35: =VLOOKUP(G35,$U$2:$AF$93,2,0) -> 0 | C35: =VLOOKUP(G35,$I$2:$T$93,2,0) -> 0 | D35: 7067 | E35: 00000129 | F35: Ex PV kVAr | G35: =D35-1 -> 7066 | I35: =R35 -> 7066 | K35: Ex_PV_kVAr | L35: 33 | M35: float | N35: AI | O35: 0.001 | P35: 0 | Q35: Ex_PV_kVAr | R35: 7066 | S35: 3 | T35: FLOAT | U35: =AD35 -> 7066 | W35: Ex_PV_kVAr | X35: 33 | Y35: float | Z35: AI | AA35: 0.001 | AB35: 0 | AC35: Ex_PV_kVAr | AD35: 7066 | AE35: 3 | AF35: FLOAT
A36: =VLOOKUP(G36,$U$2:$AF$93,2,0) -> 0 | B36: =VLOOKUP(G36,$U$2:$AF$93,2,0) -> 0 | C36: =VLOOKUP(G36,$I$2:$T$93,2,0) -> 0 | D36: 7069 | E36: 00000169 | F36: Ex kVAr-Cum | G36: =D36-1 -> 7068 | I36: =R36 -> 7068 | K36: Ex_kVAr_Cum | L36: 34 | M36: float | N36: AI | O36: 0.001 | P36: 0 | Q36: Ex_kVAr_Cum | R36: 7068 | S36: 3 | T36: FLOAT | U36: =AD36 -> 7068 | W36: Ex_kVAr_Cum | X36: 34 | Y36: float | Z36: AI | AA36: 0.001 | AB36: 0 | AC36: Ex_kVAr_Cum | AD36: 7068 | AE36: 3 | AF36: FLOAT
A37: =VLOOKUP(G37,$U$2:$AF$93,2,0) -> 0 | B37: =VLOOKUP(G37,$U$2:$AF$93,2,0) -> 0 | C37: =VLOOKUP(G37,$I$2:$T$93,2,0) -> 0 | D37: 7071 | E37: 0000E000 | F37: Ph A Volt | G37: =D37-1 -> 7070 | I37: =R37 -> 7070 | K37: Ph_A_Volt | L37: 35 | M37: float | N37: AI | O37: 1 | P37: 0 | Q37: Ph_A_Volt | R37: 7070 | S37: 3 | T37: FLOAT | U37: =AD37 -> 7070 | W37: Ph_A_Volt | X37: 35 | Y37: float | Z37: AI | AA37: 1 | AB37: 0 | AC37: Ph_A_Volt | AD37: 7070 | AE37: 3 | AF37: FLOAT
A38: =VLOOKUP(G38,$U$2:$AF$93,2,0) -> 0 | B38: =VLOOKUP(G38,$U$2:$AF$93,2,0) -> 0 | C38: =VLOOKUP(G38,$I$2:$T$93,2,0) -> 0 | D38: 7073 | E38: 0000E001 | F38: Ph B Volt | G38: =D38-1 -> 7072 | I38: =R38 -> 7072 | K38: Ph_B_Volt | L38: 36 | M38: float | N38: AI | O38: 1 | P38: 0 | Q38: Ph_B_Volt | R38: 7072 | S38: 3 | T38: FLOAT | U38: =AD38 -> 7072 | W38: Ph_B_Volt | X38: 36 | Y38: float | Z38: AI | AA38: 1 | AB38: 0 | AC38: Ph_B_Volt | AD38: 7072 | AE38: 3 | AF38: FLOAT
A39: =VLOOKUP(G39,$U$2:$AF$93,2,0) -> 0 | B39: =VLOOKUP(G39,$U$2:$AF$93,2,0) -> 0 | C39: =VLOOKUP(G39,$I$2:$T$93,2,0) -> 0 | D39: 7075 | E39: 0000E002 | F39: Ph C Volt | G39: =D39-1 -> 7074 | I39: =R39 -> 7074 | K39: Ph_C_Volt | L39: 37 | M39: float | N39: AI | O39: 1 | P39: 0 | Q39: Ph_C_Volt | R39: 7074 | S39: 3 | T39: FLOAT | U39: =AD39 -> 7074 | W39: Ph_C_Volt | X39: 37 | Y39: float | Z39: AI | AA39: 1 | AB39: 0 | AC39: Ph_C_Volt | AD39: 7074 | AE39: 3 | AF39: FLOAT
A40: =VLOOKUP(G40,$U$2:$AF$93,2,0) -> 0 | B40: =VLOOKUP(G40,$U$2:$AF$93,2,0) -> 0 | C40: =VLOOKUP(G40,$I$2:$T$93,2,0) -> 0 | D40: 7077 | E40: 0000E010 | F40: Ph A Curr | G40: =D40-1 -> 7076 | I40: =R40 -> 7076 | K40: Ph_A_Curr | L40: 38 | M40: float | N40: AI | O40: 1 | P40: 0 | Q40: Ph_A_Curr | R40: 7076 | S40: 3 | T40: FLOAT | U40: =AD40 -> 7076 | W40: Ph_A_Curr | X40: 38 | Y40: float | Z40: AI | AA40: 1 | AB40: 0 | AC40: Ph_A_Curr | AD40: 7076 | AE40: 3 | AF40: FLOAT
...

Sheet VISTEC12
A1: VT1 | B1: VT2 | C1: KVIS | E1: MODBUS VISTEC1&2&KVIS | L1: ENOS KVIS | X1: ENOS VISTEC
A2: =IF(VLOOKUP($H2,$V$2:$AG$93,2,0)="Used",VLOOKUP($H2,$V$2:$AG$93,3,0)) -> Inst_kW | B2: =IF(VLOOKUP($H2,$V$2:$AG$93,2,0)="Used",VLOOKUP($H2,$V$2:$AG$93,3,0)) -> Inst_kW | C2: =IF(VLOOKUP($H2,$V$2:$AG$93,2,0)="Used",VLOOKUP($H2,$V$2:$AG$93,3,0)) -> Inst_kW | D2: =IF(VLOOKUP($H2,$V$2:$AG$93,2,0)="Used",VLOOKUP($H2,$V$2:$AG$93,4,0)) -> 0 | E2: 7001 | F2: 0000E033 | G2: Inst kW | H2: =E2-1 -> 7000 | J2: =S2 -> 7000 | K2: Used | L2: Inst_kW | M2: 0 | N2: float | O2: AI | P2: 0.001 | Q2: 0 | R2: Inst_kW | S2: 7000 | T2: 3 | U2: FLOAT | V2: =AE2 -> 7000 | W2: Used | X2: Inst_kW | Y2: 0 | Z2: float | AA2: AI | AB2: 0.001 | AC2: 0 | AD2: Inst_kW | AE2: 7000 | AF2: 3 | AG2: FLOAT
A3: =IF(VLOOKUP($H3,$V$2:$AG$93,2,0)="Used",VLOOKUP($H3,$V$2:$AG$93,3,0)) -> Inst_kVAr | B3: =IF(VLOOKUP($H3,$V$2:$AG$93,2,0)="Used",VLOOKUP($H3,$V$2:$AG$93,3,0)) -> Inst_kVAr | C3: =IF(VLOOKUP($H3,$V$2:$AG$93,2,0)="Used",VLOOKUP($H3,$V$2:$AG$93,3,0)) -> Inst_kVAr | D3: =IF(VLOOKUP($H3,$V$2:$AG$93,2,0)="Used",VLOOKUP($H3,$V$2:$AG$93,4,0)) -> 1 | E3: 7003 | F3: 0000E043 | G3: Inst kVAr | H3: =E3-1 -> 7002 | J3: =S3 -> 7002 | K3: Used | L3: Inst_kVAr | M3: 1 | N3: float | O3: AI | P3: 0.001 | Q3: 0 | R3: Inst_kVAr | S3: 7002 | T3: 3 | U3: FLOAT | V3: =AE3 -> 7002 | W3: Used | X3: Inst_kVAr | Y3: 1 | Z3: float | AA3: AI | AB3: 0.001 | AC3: 0 | AD3: Inst_kVAr | AE3: 7002 | AF3: 3 | AG3: FLOAT
A4: =IF(VLOOKUP($H4,$V$2:$AG$93,2,0)="Used",VLOOKUP($H4,$V$2:$AG$93,3,0)) -> Ex_Total_kWh | B4: =IF(VLOOKUP($H4,$V$2:$AG$93,2,0)="Used",VLOOKUP($H4,$V$2:$AG$93,3,0)) -> Ex_Total_kWh | C4: =IF(VLOOKUP($H4,$V$2:$AG$93,2,0)="Used",VLOOKUP($H4,$V$2:$AG$93,3,0)) -> Ex_Total_kWh | D4: =IF(VLOOKUP($H4,$V$2:$AG$93,2,0)="Used",VLOOKUP($H4,$V$2:$AG$93,4,0)) -> 2 | E4: 7005 | F4: 00000069 | G4: Ex Total kWh | H4: =E4-1 -> 7004 | J4: =S4 -> 7004 | K4: Used | L4: Ex_Total_kWh | M4: 2 | N4: float | O4: AI | P4: 0.001 | Q4: 0 | R4: Ex_Total_kWh | S4: 7004 | T4: 3 | U4: FLOAT | V4: =AE4 -> 7004 | W4: Used | X4: Ex_Total_kWh | Y4: 2 | Z4: float | AA4: AI | AB4: 0.001 | AC4: 0 | AD4: Ex_Total_kWh | AE4: 7004 | AF4: 3 | AG4: FLOAT
A5: =IF(VLOOKUP($H5,$V$2:$AG$93,2,0)="Used",VLOOKUP($H5,$V$2:$AG$93,3,0)) -> Ex_kWh_RateA | B5: =IF(VLOOKUP($H5,$V$2:$AG$93,2,0)="Used",VLOOKUP($H5,$V$2:$AG$93,3,0)) -> Ex_kWh_RateA | C5: =IF(VLOOKUP($H5,$V$2:$AG$93,2,0)="Used",VLOOKUP($H5,$V$2:$AG$93,3,0)) -> Ex_kWh_RateA | D5: =IF(VLOOKUP($H5,$V$2:$AG$93,2,0)="Used",VLOOKUP($H5,$V$2:$AG$93,4,0)) -> 3 | E5: 7007 | F5: 00000000 | G5: Ex kWh RateA | H5: =E5-1 -> 7006 | J5: =S5 -> 7006 | K5: Used | L5: Ex_kWh_RateA | M5: 3 | N5: float | O5: AI | P5: 0.001 | Q5: 0 | R5: Ex_kWh_RateA | S5: 7006 | T5: 3 | U5: FLOAT | V5: =AE5 -> 7006 | W5: Used | X5: Ex_kWh_RateA | Y5: 3 | Z5: float | AA5: AI | AB5: 0.001 | AC5: 0 | AD5: Ex_kWh_RateA | AE5: 7006 | AF5: 3 | AG5: FLOAT
A6: =IF(VLOOKUP($H6,$V$2:$AG$93,2,0)="Used",VLOOKUP($H6,$V$2:$AG$93,3,0)) -> Ex_kWh_RateB | B6: =IF(VLOOKUP($H6,$V$2:$AG$93,2,0)="Used",VLOOKUP($H6,$V$2:$AG$93,3,0)) -> Ex_kWh_RateB | C6: =IF(VLOOKUP($H6,$V$2:$AG$93,2,0)="Used",VLOOKUP($H6,$V$2:$AG$93,3,0)) -> Ex_kWh_RateB | D6: =IF(VLOOKUP($H6,$V$2:$AG$93,2,0)="Used",VLOOKUP($H6,$V$2:$AG$93,4,0)) -> 4 | E6: 7009 | F6: 00000001 | G6: Ex kWh RateB | H6: =E6-1 -> 7008 | J6: =S6 -> 7008 | K6: Used | L6: Ex_kWh_RateB | M6: 4 | N6: float | O6: AI | P6: 0.001 | Q6: 0 | R6: Ex_kWh_RateB | S6: 7008 | T6: 3 | U6: FLOAT | V6: =AE6 -> 7008 | W6: Used | X6: Ex_kWh_RateB | Y6: 4 | Z6: float | AA6: AI | AB6: 0.001 | AC6: 0 | AD6: Ex_kWh_RateB | AE6: 7008 | AF6: 3 | AG6: FLOAT
A7: =IF(VLOOKUP($H7,$V$2:$AG$93,2,0)="Used",VLOOKUP($H7,$V$2:$AG$93,3,0)) -> Ex_kWh_RateC | B7: =IF(VLOOKUP($H7,$V$2:$AG$93,2,0)="Used",VLOOKUP($H7,$V$2:$AG$93,3,0)) -> Ex_kWh_RateC | C7: =IF(VLOOKUP($H7,$V$2:$AG$93,2,0)="Used",VLOOKUP($H7,$V$2:$AG$93,3,0)) -> Ex_kWh_RateC | D7: =IF(VLOOKUP($H7,$V$2:$AG$93,2,0)="Used",VLOOKUP($H7,$V$2:$AG$93,4,0)) -> 5 | E7: 7011 | F7: 00000002 | G7: Ex kWh RateC | H7: =E7-1 -> 7010 | J7: =S7 -> 7010 | K7: Used | L7: Ex_kWh_RateC | M7: 5 | N7: float | O7: AI | P7: 0.001 | Q7: 0 | R7: Ex_kWh_RateC | S7: 7010 | T7: 3 | U7: FLOAT | V7: =AE7 -> 7010 | W7: Used | X7: Ex_kWh_RateC | Y7: 5 | Z7: float | AA7: AI | AB7: 0.001 | AC7: 0 | AD7: Ex_kWh_RateC | AE7: 7010 | AF7: 3 | AG7: FLOAT
A8: =IF(VLOOKUP($H8,$V$2:$AG$93,2,0)="Used",VLOOKUP($H8,$V$2:$AG$93,3,0)) -> FALSE | B8: =IF(VLOOKUP($H8,$V$2:$AG$93,2,0)="Used",VLOOKUP($H8,$V$2:$AG$93,3,0)) -> FALSE | C8: =IF(VLOOKUP($H8,$V$2:$AG$93,2,0)="Used",VLOOKUP($H8,$V$2:$AG$93,3,0)) -> FALSE | D8: =IF(VLOOKUP($H8,$V$2:$AG$93,2,0)="Used",VLOOKUP($H8,$V$2:$AG$93,4,0)) -> FALSE | E8: 7013 | F8: 00001000 | G8: Ex Max kW A | H8: =E8-1 -> 7012 | J8: =S8 -> 7012 | L8: Ex_Max_kW_A | M8: 6 | N8: float | O8: AI | P8: 0.001 | Q8: 0 | R8: Ex_Max_kW_A | S8: 7012 | T8: 3 | U8: FLOAT | V8: =AE8 -> 7012 | X8: Ex_Max_kW_A | Y8: 6 | Z8: float | AA8: AI | AB8: 0.001 | AC8: 0 | AD8: Ex_Max_kW_A | AE8: 7012 | AF8: 3 | AG8: FLOAT
A9: =IF(VLOOKUP($H9,$V$2:$AG$93,2,0)="Used",VLOOKUP($H9,$V$2:$AG$93,3,0)) -> FALSE | B9: =IF(VLOOKUP($H9,$V$2:$AG$93,2,0)="Used",VLOOKUP($H9,$V$2:$AG$93,3,0)) -> FALSE | C9: =IF(VLOOKUP($H9,$V$2:$AG$93,2,0)="Used",VLOOKUP($H9,$V$2:$AG$93,3,0)) -> FALSE | D9: =IF(VLOOKUP($H9,$V$2:$AG$93,2,0)="Used",VLOOKUP($H9,$V$2:$AG$93,4,0)) -> FALSE | E9: 7015 | F9: 00001001 | G9: Ex Max kW B | H9: =E9-1 -> 7014 | J9: =S9 -> 7014 | L9: Ex_Max_kW_B | M9: 7 | N9: float | O9: AI | P9: 0.001 | Q9: 0 | R9: Ex_Max_kW_B | S9: 7014 | T9: 3 | U9: FLOAT | V9: =AE9 -> 7014 | X9: Ex_Max_kW_B | Y9: 7 | Z9: float | AA9: AI | AB9: 0.001 | AC9: 0 | AD9: Ex_Max_kW_B | AE9: 7014 | AF9: 3 | AG9: FLOAT
A10: =IF(VLOOKUP($H10,$V$2:$AG$93,2,0)="Used",VLOOKUP($H10,$V$2:$AG$93,3,0)) -> FALSE | B10: =IF(VLOOKUP($H10,$V$2:$AG$93,2,0)="Used",VLOOKUP($H10,$V$2:$AG$93,3,0)) -> FALSE | C10: =IF(VLOOKUP($H10,$V$2:$AG$93,2,0)="Used",VLOOKUP($H10,$V$2:$AG$93,3,0)) -> FALSE | D10: =IF(VLOOKUP($H10,$V$2:$AG$93,2,0)="Used",VLOOKUP($H10,$V$2:$AG$93,4,0)) -> FALSE | E10: 7017 | F10: 00001002 | G10: Ex Max kW C | H10: =E10-1 -> 7016 | J10: =S10 -> 7016 | L10: Ex_Max_kW_C | M10: 8 | N10: float | O10: AI | P10: 0.001 | Q10: 0 | R10: Ex_Max_kW_C | S10: 7016 | T10: 3 | U10: FLOAT | V10: =AE10 -> 7016 | X10: Ex_Max_kW_C | Y10: 8 | Z10: float | AA10: AI | AB10: 0.001 | AC10: 0 | AD10: Ex_Max_kW_C | AE10: 7016 | AF10: 3 | AG10: FLOAT
A11: =IF(VLOOKUP($H11,$V$2:$AG$93,2,0)="Used",VLOOKUP($H11,$V$2:$AG$93,3,0)) -> FALSE | B11: =IF(VLOOKUP($H11,$V$2:$AG$93,2,0)="Used",VLOOKUP($H11,$V$2:$AG$93,3,0)) -> FALSE | C11: =IF(VLOOKUP($H11,$V$2:$AG$93,2,0)="Used",VLOOKUP($H11,$V$2:$AG$93,3,0)) -> FALSE | D11: =IF(VLOOKUP($H11,$V$2:$AG$93,2,0)="Used",VLOOKUP($H11,$V$2:$AG$93,4,0)) -> FALSE | E11: 7019 | F11: 00001040 | G11: Ex kW-Cum A | H11: =E11-1 -> 7018 | J11: =S11 -> 7018 | L11: Ex_kW_Cum_A | M11: 9 | N11: float | O11: AI | P11: 0.001 | Q11: 0 | R11: Ex_kW_Cum_A | S11: 7018 | T11: 3 | U11: FLOAT | V11: =AE11 -> 7018 | X11: Ex_kW_Cum_A | Y11: 9 | Z11: float | AA11: AI | AB11: 0.001 | AC11: 0 | AD11: Ex_kW_Cum_A | AE11: 7018 | AF11: 3 | AG11: FLOAT
A12: =IF(VLOOKUP($H12,$V$2:$AG$93,2,0)="Used",VLOOKUP($H12,$V$2:$AG$93,3,0)) -> FALSE | B12: =IF(VLOOKUP($H12,$V$2:$AG$93,2,0)="Used",VLOOKUP($H12,$V$2:$AG$93,3,0)) -> FALSE | C12: =IF(VLOOKUP($H12,$V$2:$AG$93,2,0)="Used",VLOOKUP($H12,$V$2:$AG$93,3,0)) -> FALSE | D12: =IF(VLOOKUP($H12,$V$2:$AG$93,2,0)="Used",VLOOKUP($H12,$V$2:$AG$93,4,0)) -> FALSE | E12: 7021 | F12: 00001041 | G12: Ex kW-Cum B | H12: =E12-1 -> 7020 | J12: =S12 -> 7020 | L12: Ex_kW_Cum_B | M12: 10 | N12: float | O12: AI | P12: 0.001 | Q12: 0 | R12: Ex_kW_Cum_B | S12: 7020 | T12: 3 | U12: FLOAT | V12: =AE12 -> 7020 | X12: Ex_kW_Cum_B | Y12: 10 | Z12: float | AA12: AI | AB12: 0.001 | AC12: 0 | AD12: Ex_kW_Cum_B | AE12: 7020 | AF12: 3 | AG12: FLOAT
A13: =IF(VLOOKUP($H13,$V$2:$AG$93,2,0)="Used",VLOOKUP($H13,$V$2:$AG$93,3,0)) -> FALSE | B13: =IF(VLOOKUP($H13,$V$2:$AG$93,2,0)="Used",VLOOKUP($H13,$V$2:$AG$93,3,0)) -> FALSE | C13: =IF(VLOOKUP($H13,$V$2:$AG$93,2,0)="Used",VLOOKUP($H13,$V$2:$AG$93,3,0)) -> FALSE | D13: =IF(VLOOKUP($H13,$V$2:$AG$93,2,0)="Used",VLOOKUP($H13,$V$2:$AG$93,4,0)) -> FALSE | E13: 7023 | F13: 00001042 | G13: Ex kW-Cum C | H13: =E13-1 -> 7022 | J13: =S13 -> 7022 | L13: Ex_kW_Cum_C | M13: 11 | N13: float | O13: AI | P13: 0.001 | Q13: 0 | R13: Ex_kW_Cum_C | S13: 7022 | T13: 3 | U13: FLOAT | V13: =AE13 -> 7022 | X13: Ex_kW_Cum_C | Y13: 11 | Z13: float | AA13: AI | AB13: 0.001 | AC13: 0 | AD13: Ex_kW_Cum_C | AE13: 7022 | AF13: 3 | AG13: FLOAT
A14: =IF(VLOOKUP($H14,$V$2:$AG$93,2,0)="Used",VLOOKUP($H14,$V$2:$AG$93,3,0)) -> Ex_Total_kVArh | B14: =IF(VLOOKUP($H14,$V$2:$AG$93,2,0)="Used",VLOOKUP($H14,$V$2:$AG$93,3,0)) -> Ex_Total_kVArh | C14: =IF(VLOOKUP($H14,$V$2:$AG$93,2,0)="Used",VLOOKUP($H14,$V$2:$AG$93,3,0)) -> Ex_Total_kVArh | D14: =IF(VLOOKUP($H14,$V$2:$AG$93,2,0)="Used",VLOOKUP($H14,$V$2:$AG$93,4,0)) -> 12 | E14: 7025 | F14: 00000169 | G14: Ex Total kVArh | H14: =E14-1 -> 7024 | J14: =S14 -> 7024 | K14: Used | L14: Ex_Total_kVArh | M14: 12 | N14: float | O14: AI | P14: 0.001 | Q14: 0 | R14: Ex_Total_kVArh | S14: 7024 | T14: 3 | U14: FLOAT | V14: =AE14 -> 7024 | W14: Used | X14: Ex_Total_kVArh | Y14: 12 | Z14: float | AA14: AI | AB14: 0.001 | AC14: 0 | AD14: Ex_Total_kVArh | AE14: 7024 | AF14: 3 | AG14: FLOAT
A15: =IF(VLOOKUP($H15,$V$2:$AG$93,2,0)="Used",VLOOKUP($H15,$V$2:$AG$93,3,0)) -> FALSE | B15: =IF(VLOOKUP($H15,$V$2:$AG$93,2,0)="Used",VLOOKUP($H15,$V$2:$AG$93,3,0)) -> FALSE | C15: =IF(VLOOKUP($H15,$V$2:$AG$93,2,0)="Used",VLOOKUP($H15,$V$2:$AG$93,3,0)) -> FALSE | D15: =IF(VLOOKUP($H15,$V$2:$AG$93,2,0)="Used",VLOOKUP($H15,$V$2:$AG$93,4,0)) -> FALSE | E15: 7027 | F15: 00000160 | G15: Ex kVArh A | H15: =E15-1 -> 7026 | J15: =S15 -> 7026 | L15: Ex_kVArh_RateA | M15: 13 | N15: float | O15: AI | P15: 0.001 | Q15: 0 | R15: Ex_kVArh_RateA | S15: 7026 | T15: 3 | U15: FLOAT | V15: =AE15 -> 7026 | X15: Ex_kVArh_RateA | Y15: 13 | Z15: float | AA15: AI | AB15: 0.001 | AC15: 0 | AD15: Ex_kVArh_RateA | AE15: 7026 | AF15: 3 | AG15: FLOAT
A16: =IF(VLOOKUP($H16,$V$2:$AG$93,2,0)="Used",VLOOKUP($H16,$V$2:$AG$93,3,0)) -> FALSE | B16: =IF(VLOOKUP($H16,$V$2:$AG$93,2,0)="Used",VLOOKUP($H16,$V$2:$AG$93,3,0)) -> FALSE | C16: =IF(VLOOKUP($H16,$V$2:$AG$93,2,0)="Used",VLOOKUP($H16,$V$2:$AG$93,3,0)) -> FALSE | D16: =IF(VLOOKUP($H16,$V$2:$AG$93,2,0)="Used",VLOOKUP($H16,$V$2:$AG$93,4,0)) -> FALSE | E16: 7029 | F16: 00000161 | G16: Ex kVArh B | H16: =E16-1 -> 7028 | J16: =S16 -> 7028 | L16: Ex_kVArh_RateB | M16: 14 | N16: float | O16: AI | P16: 0.001 | Q16: 0 | R16: Ex_kVArh_RateB | S16: 7028 | T16: 3 | U16: FLOAT | V16: =AE16 -> 7028 | X16: Ex_kVArh_RateB | Y16: 14 | Z16: float | AA16: AI | AB16: 0.001 | AC16: 0 | AD16: Ex_kVArh_RateB | AE16: 7028 | AF16: 3 | AG16: FLOAT
A17: =IF(VLOOKUP($H17,$V$2:$AG$93,2,0)="Used",VLOOKUP($H17,$V$2:$AG$93,3,0)) -> FALSE | B17: =IF(VLOOKUP($H17,$V$2:$AG$93,2,0)="Used",VLOOKUP($H17,$V$2:$AG$93,3,0)) -> FALSE | C17: =IF(VLOOKUP($H17,$V$2:$AG$93,2,0)="Used",VLOOKUP($H17,$V$2:$AG$93,3,0)) -> FALSE | D17: =IF(VLOOKUP($H17,$V$2:$AG$93,2,0)="Used",VLOOKUP($H17,$V$2:$AG$93,4,0)) -> FALSE | E17: 7031 | F17: 00000162 | G17: Ex kVArh C | H17: =E17-1 -> 7030 | J17: =S17 -> 7030 | L17: Ex_kVArh_RateC | M17: 15 | N17: float | O17: AI | P17: 0.001 | Q17: 0 | R17: Ex_kVArh_RateC | S17: 7030 | T17: 3 | U17: FLOAT | V17: =AE17 -> 7030 | X17: Ex_kVArh_RateC | Y17: 15 | Z17: float | AA17: AI | AB17: 0.001 | AC17: 0 | AD17: Ex_kVArh_RateC | AE17: 7030 | AF17: 3 | AG17: FLOAT
